<mujoco model="mini_owheel_learning">
  <compiler angle="radian" autolimits="true" />

  <asset>
    <!--设置地板-->
    <texture name="grid" type="2d" builtin="checker" width="512" height="512" rgb1=".1 .2 .3"
      rgb2=".2 .3 .4" />
    <material name="grid" texture="grid" texrepeat="1 1" texuniform="true" reflectance=".2" />
  </asset>

  <option timestep="0.001" integrator="RK4">
    <flag sensornoise="enable" />
  </option>

  <visual>
    <map force="0.1" zfar="30" />
    <rgba haze="0.15 0.25 0.35 1" />
    <global offwidth="2560" offheight="1440" elevation="-20" azimuth="120" />
  </visual>

  <statistic meansize="0.166499" extent="1.17243" center="0 0.000784361 -0.300364" />
  <worldbody>
    <!--主光源（头顶）-->
    <light name="main_light" diffuse="2 2 2" specular="0.5 0.5 0.5" pos="0 0 40" dir="0 0 -1"
      castshadow="true" />
    <!--辅助光源,四面八方-->
    <light name="aux_light1" diffuse=".8 .8 .8" pos=" 10 0 1" dir="-1 0 0" castshadow="false" />
    <light name="aux_light2" diffuse=".8 .8 .8" pos="-10 0 1" dir=" 1 0 0" castshadow="false" />
    <light name="aux_light3" diffuse=".8 .8 .8" pos="0  10 1" dir="0 -1 0" castshadow="false" />
    <light name="aux_light4" diffuse=".8 .8 .8" pos="0 -10 1" dir="0  1 0" castshadow="false" />
    <!--地板-->
    <geom name="floor" type="plane" size="0 0 0.05" material="grid" />
    <body name="torso" pos="0 0 0.82" euler="0 0 3.14">
      <inertial pos="0.01278331 -0.00050323 0.04958380" mass="14.481360"
        fullinertia="0.172446 0.146211 0.128072 -0.000378 0.030596 0.001862" />
      <freejoint name="torso" />
      <geom size="0.12 0.16 0.125" pos="0 0 0.05" type="box" rgba="0.752941 0.752941 0.752941 1" />
      <!--增加IMU所在位置-->
      <site name="imu_site" pos="0 0 0" size="0.02" rgba="1 0 0 1" type="sphere" />
      <body name="lhip" pos="-0.0694983 0.0850001 -0.103336">
        <inertial pos="0.069765 -0.005664 -4e-05" quat="0.506314 0.486654 0.492399 0.514157"
          mass="1.41138" diaginertia="0.000793082 0.00068858 0.000350338" />
        <joint name="lhiproll" pos="0 0 0" axis="1 0 0" range="-0.5 0.5" />
        <body name="lfem" pos="0.0705 0.019725 0">
          <inertial pos="2.9e-05 0.039864 -0.053092" quat="0.997185 0.0702586 -0.00189156 0.0261344"
            mass="1.94987" diaginertia="0.0193461 0.0193218 0.000969153" />
          <joint name="lfempitch" pos="0 0 0" axis="0 -1 0" range="-1.05 1.05" />
          <geom size="0.03 0.085" pos="0 0 -0.15" type="cylinder"
            rgba="0.752941 0.752941 0.752941 1" />
          <body name="ltib" pos="0 0.0162685 -0.3">
            <inertial pos="0.000378 0.004765 -0.218009" quat="0.666459 -0.0145818 0.0101508 0.74533"
              mass="1.48393" diaginertia="0.0148939 0.0148302 0.000594952" />
            <joint name="ltibpitch" pos="0 0 0" axis="0 -1 0" range="-1.57 0" />
            <geom size="0.03 0.14" pos="0 0 -0.18" type="cylinder"
              rgba="0.752941 0.752941 0.752941 1" />
            <body name="lfoot" pos="0 0.03115 -0.3">
              <inertial pos="-0.00017 -0.022829 -0.054307"
                quat="0.437705 0.555194 0.436653 0.556335" mass="0.393722"
                diaginertia="0.0012156 0.000988402 0.000539998" />
              <joint name="lfootrot" pos="0 0 0" axis="0 1 0" range="-1.57 1.57" />
              <geom size="0.1 0.015 0.005" pos="0 -0.03 -0.082" type="box"
                rgba="0.752941 0.752941 0.752941 1" />
            </body>
          </body>
        </body>
      </body>
      <body name="rhip" pos="-0.0694983 -0.0849999 -0.103336">
        <inertial pos="0.069787 0.005664 -2e-06" quat="0.492399 0.514157 0.506314 0.486654"
          mass="1.41138" diaginertia="0.000793082 0.00068858 0.000350338" />
        <joint name="rhiproll" pos="0 0 0" axis="1 0 0" range="-0.5 0.5" />
        <body name="rfem" pos="0.0705 -0.019725 0">
          <inertial pos="0 -0.039784 -0.053142" quat="0.997491 -0.0707435 -0.000207624 -0.00254665"
            mass="1.94987" diaginertia="0.019343 0.0193154 0.000971618" />
          <joint name="rfempitch" pos="0 0 0" axis="0 -1 0" range="-1.05 1.05" />
          <geom size="0.03 0.085" pos="0 0 -0.15" type="cylinder"
            rgba="0.752941 0.752941 0.752941 1" />
          <body name="rtib" pos="0 -0.0147 -0.3">
            <inertial pos="0.000328 -0.004765 -0.218009"
              quat="0.746449 0.0100612 -0.0147449 0.665203" mass="1.48393"
              diaginertia="0.014894 0.0148302 0.000594782" />
            <joint name="rtibpitch" pos="0 0 0" axis="0 -1 0" range="-1.57 0" />
            <geom size="0.03 0.14" pos="0 0 -0.18" type="cylinder"
              rgba="0.752941 0.752941 0.752941 1" />
            <body name="rfoot" pos="0 -0.03115 -0.3">
              <inertial pos="4.8e-05 0.022829 -0.054307" quat="0.553748 0.439757 0.557769 0.434593"
                mass="0.393722" diaginertia="0.0012156 0.000988438 0.000542962" />
              <joint name="rfootrot" pos="0 0 0" axis="0 1 0" range="-1.57 1.57" />
              <geom size="0.1 0.015 0.005" pos="0 0.03 -0.082" type="box"
                rgba="0.752941 0.752941 0.752941 1" />
            </body>
          </body>
        </body>
      </body>
    </body>
  </worldbody>

  <actuator>
    <!--腿-->
    <motor name="lhiproll" joint="lhiproll" gear="1" ctrllimited="true" ctrlrange="-100 100" />
    <motor name="lfempitch" joint="lfempitch" gear="1" ctrllimited="true" ctrlrange="-100 100" />
    <motor name="ltibpitch" joint="ltibpitch" gear="1" ctrllimited="true" ctrlrange="-100 100" />
    <motor name="lfootrot" joint="lfootrot" gear="1" ctrllimited="true" ctrlrange="-100 100" />
    <motor name="rhiproll" joint="rhiproll" gear="1" ctrllimited="true" ctrlrange="-100 100" />
    <motor name="rfempitch" joint="rfempitch" gear="1" ctrllimited="true" ctrlrange="-100 100" />
    <motor name="rtibpitch" joint="rtibpitch" gear="1" ctrllimited="true" ctrlrange="-100 100" />
    <motor name="rfootrot" joint="rfootrot" gear="1" ctrllimited="true" ctrlrange="-100 100" />
  </actuator>

  <sensor>
    <!--组合IMU-->
    <accelerometer name="imu_acc" site="imu_site" />
    <gyro name="imu_gyro" site="imu_site" />
    <framepos name="imu_pos" objtype="site" objname="imu_site" />
    <framelinvel name="imu_linvel" objtype="site" objname="imu_site" />
  </sensor>

</mujoco>